Run python cleanProxiesRowUrl.py
Traceback (most recent call last):
  File "/home/runner/work/xray-proxy-grabber-telegram/xray-proxy-grabber-telegram/cleanProxiesRowUrl.py", line 8, in <module>
    from gitRepo import getLatestActiveConfigs, getLatestRowProxies, commitPushRowProxiesFile
  File "/home/runner/work/xray-proxy-grabber-telegram/xray-proxy-grabber-telegram/gitRepo.py", line 16, in <module>
    repo = Repo.clone_from(
  File "/opt/hostedtoolcache/Python/3.10.15/x64/lib/python3.10/site-packages/git/repo/base.py", line 1327, in clone_from
    return cls._clone(
  File "/opt/hostedtoolcache/Python/3.10.15/x64/lib/python3.10/site-packages/git/repo/base.py", line 1236, in _clone
    finalize_process(proc, stderr=stderr)
  File "/opt/hostedtoolcache/Python/3.10.15/x64/lib/python3.10/site-packages/git/util.py", line 419, in finalize_process
    proc.wait(**kwargs)
  File "/opt/hostedtoolcache/Python/3.10.15/x64/lib/python3.10/site-packages/git/cmd.py", line 604, in wait
    raise GitCommandError(remove_password_if_present(self.args), status, errstr)
git.exc.GitCommandError: Cmd('git') failed due to: exit code(128)
  cmdline: git clone -v -- ********g*****i*****t*****h*****u*****b*****.*****c*****o*****m*****/ ./repo
  stderr: 'Cloning into './repo'...
fatal: repository 'https://github.com/' not found
'
Error: Process completed with exit code 1.name: clean-row-proxies-schedule

on:
 schedule:
   - cron: "30 */1 * * *"

jobs:
  clean-row-urls:
    runs-on: ubuntu-latest
    env:
      FARSHID_TOKEN: ${{ secrets.GG_FARSHID_TOKEN }}
      REPO: ${{ secrets.REPO }}
      DEBUG_MODE: 0
    steps:
      - uses: actions/checkout@v3
      - name: Install Python
        uses: actions/setup-python@v4
        with:
          python-version: '3.10'
          cache: 'pip'
      - name: Install Dependencies
        run: pip install -r requirements.txt
        shell: bash
      - name: clean urls
        run: python cleanProxiesRowUrl.py
        shell: bash
